<?xml version="1.0"?>
<robot xmlns:xacro="http://www.ros.org/wiki/xacro" name="gurdy">
    
    <gazebo>
        <plugin name="gazebo_ros_control" filename="libgazebo_ros_control.so">
            <robotNamespace>/gurdy</robotNamespace>
        </plugin>
    </gazebo>
    
    <!-- MACROS -->
    <xacro:macro name="upperleg_link" params="number">
        <link name="upperleg_M${number}_link">
     	    <inertial>
                <origin xyz="0 0 0.03" rpy="0 0 0"/>
                <mass value="0.01" />
                <inertia ixx="3.015625e-05" ixy="0.0" ixz="0.0" iyy="3.015625e-05" iyz="0.0" izz="3.125e-07"/>
            </inertial>
            <collision>
                <origin xyz="0 0 0.03" rpy="0 0 0"/>
                <geometry>
                    <cylinder length="0.06" radius="0.0025"/>
                </geometry>
            </collision>
            <visual>
                <origin rpy="0.0 0 0" xyz="0 0 0"/>
                <geometry>
                    <mesh filename="package://my_gurdy_description/models/gurdy/meshes/gurdy_higherleg_v2.dae"/>
                </geometry>
            </visual>
    	</link>
    </xacro:macro>
    
    <xacro:macro name="lowerleg_link" params="number">
        <link name="lowerleg_M${number}_link">
     	    <inertial>
                <origin xyz="0 0 0.03" rpy="0 0 0"/>
                <mass value="0.01" />
                <inertia ixx="3.005625e-05" ixy="0.0" ixz="0.0" iyy="3.005625e-05" iyz="0.0" izz="1.125e-07"/>
            </inertial>
            <collision>
                <origin xyz="0 0 0.03" rpy="0 0 0"/>
                <geometry>
                    <cylinder length="0.06" radius="0.0015"/>
                </geometry>
            </collision>
            <visual>
                <origin rpy="0.0 0 0" xyz="0 0 0"/>
                <geometry>
                    <mesh filename="package://my_gurdy_description/models/gurdy/meshes/gurdy_lowerleg_v2.dae"/>
                </geometry>
            </visual>
    	</link>
        <joint name="upperlegM${number}_lowerlegM${number}_joint" type="revolute">
        	<parent link="upperleg_M${number}_link"/>
        	<child link="lowerleg_M${number}_link"/>
            <origin xyz="0 0.0095 0.06" rpy="0 0 3.14159"/>
            <limit lower="-2.9" upper="1.5708" effort="1.0" velocity="0.005"/>
            <axis xyz="0 1 0"/>
    	</joint>
    </xacro:macro>
    
    <xacro:macro name="foot_link" params="number colour">
        <link name="footM${number}_link">
     	    <inertial>
                <origin xyz="0 0 0" rpy="0 0 0"/>
                <mass value="0.01" />
                <inertia ixx="1.28e-06" ixy="0.0" ixz="0.0" iyy="1.28e-06" iyz="0.0" izz="1.28e-06"/>
            </inertial>
            <collision>
                <origin xyz="0 0 0" rpy="0 0 0"/>
                <geometry>
                    <sphere radius="0.008"/>
                </geometry>
            </collision>
            <visual>
                <origin rpy="0.0 0 0" xyz="0 0 0"/>
                <geometry>
                    <sphere radius="0.008"/>
                </geometry>
            </visual>
    	</link>
        <gazebo reference="footM${number}_link">
            <kp>1000.0</kp>
            <kd>1000.0</kd>
            <mu1>10.0</mu1>
            <mu2>10.0</mu2>
            <material>Gazebo/${colour}</material>
        </gazebo>
        <joint name="basefoot_peg_M${number}_basefoot_peg_M${number}_joint_joint" type="fixed">
            <parent link="lowerleg_M${number}_link"/>
            <child link="footM${number}_link"/>
            <origin xyz="0 0 0.06" rpy="0 0 0"/>
        </joint>
    </xacro:macro>
    
    <xacro:macro name="upper_transmission" params="number">
        <transmission name="tran${number}">
            <type>transmission_interface/SimpleTransmission</type>
            <joint name="head_upperlegM${number}_joint">
                <hardwareInterface>EffortJointInterface</hardwareInterface>
            </joint>
            <actuator name="motor${number}">
                <hardwareInterface>EffortJointInterface</hardwareInterface>
                <mechanicalReduction>1</mechanicalReduction>
            </actuator>
        </transmission>
    </xacro:macro>
    
    <xacro:macro name="lower_transmission" params="number number_transm">
        
        <transmission name="tran${number_transm}">
            <type>transmission_interface/SimpleTransmission</type>
            <joint name="upperlegM${number}_lowerlegM${number}_joint">
                <hardwareInterface>EffortJointInterface</hardwareInterface>
            </joint>
            <actuator name="motor${number_transm}">
                <hardwareInterface>EffortJointInterface</hardwareInterface>
                <mechanicalReduction>1</mechanicalReduction>
            </actuator>
        </transmission>
    </xacro:macro>
    
    <material name="blue">
        <color rgba="0 0 0.8 1"/>
    </material>
    <material name="red">
        <color rgba="0.8 0 0 1"/>
    </material>
    <material name="green">
        <color rgba="0 0.8 0 1"/>
    </material>
    
	<!-- * * * Link Definitions * * * -->

    <link name="base_link">
        <collision>
            <origin xyz="0 0 0" rpy="0 0 0"/>
            <geometry>
                <box size="0.01 0.01 0.01"/>
            </geometry>
        </collision>
		<visual>
		    <origin xyz="0 0 0.01" rpy="0 0 0"/>
			<geometry>
				<box size="0.01 0.01 0.01"/>
			</geometry>
		</visual>
	</link>

    <link name="head_link">
 	    <inertial>
            <origin xyz="0 0 0.02" rpy="0 0 0"/>
            <mass value="0.01" />
            <inertia ixx="7.58333333333e-07" ixy="0.0" ixz="0.0" iyy="7.58333333333e-07" iyz="0.0" izz="1.25e-06"/>
        </inertial>
        <collision>
            <origin xyz="0 0 0.02" rpy="0 0 0"/>
            <geometry>
                <cylinder radius="0.05" length="0.04"/>
            </geometry>
        </collision>
        <visual>
            <origin rpy="0.0 0 0" xyz="0 0 0"/>
            <geometry>
                <mesh filename="package://my_gurdy_description/models/gurdy/meshes/gurdy_head_v2.dae"/>
            </geometry>
        </visual>
	</link>

    <gazebo reference="head_link">
        <mu1>10.0</mu1>
        <mu2>10.0</mu2>
    </gazebo>

    <joint name="fixed" type="fixed">
        <parent link="base_link"/>
        <child link="head_link"/>
    </joint>

    <xacro:upperleg_link number="1"/>
    <xacro:upper_transmission number="1"/>

    <xacro:upperleg_link number="2"/>
    <xacro:upper_transmission number="2"/>

    <xacro:upperleg_link number="3"/>
    <xacro:upper_transmission number="3"/>


    <joint name="head_upperlegM1_joint" type="revolute">
    	<parent link="head_link"/>
    	<child link="upperleg_M1_link"/>
        <origin xyz="-0.02165 -0.0125 -0.008" rpy="3.14159 0 0.523599"/>
        <limit lower="-1.55" upper="0.0" effort="1.0" velocity="0.005"/>
        <axis xyz="0 1 0"/>
	</joint>
	
	<joint name="head_upperlegM2_joint" type="revolute">
    	<parent link="head_link"/>
    	<child link="upperleg_M2_link"/>
        <origin xyz="0.02165 -0.0125 -0.008" rpy="3.14159 0 2.61799"/>
        <limit lower="-1.55" upper="0.0" effort="1.0" velocity="0.005"/>
        <axis xyz="0 1 0"/>
	</joint>
	
	<joint name="head_upperlegM3_joint" type="revolute">
    	<parent link="head_link"/>
    	<child link="upperleg_M3_link"/>
        <origin xyz="0 0.025 -0.008" rpy="3.14159 0 -1.5708"/>
        <limit lower="-1.55" upper="0.0" effort="1.0" velocity="0.005"/>
        <axis xyz="0 1 0"/>
	</joint>



    <xacro:lowerleg_link number="1"/>
    <xacro:lower_transmission number="1" number_transm="4"/>

    <xacro:lowerleg_link number="2"/>
    <xacro:lower_transmission number="2" number_transm="5"/>
    

    <xacro:lowerleg_link number="3"/>
    <xacro:lower_transmission number="3" number_transm="6"/>
    

    <xacro:foot_link number="1" colour="Red"/>
    <xacro:foot_link number="2" colour="Green"/>
    <xacro:foot_link number="3" colour="Blue"/>

    <gazebo>
        <plugin name="gazebo_ros_imu_controller" filename="libgazebo_ros_imu.so">
          <robotNamespace>/gurdy</robotNamespace>
          <topicName>imu/data</topicName>
          <serviceName>imu/service</serviceName>
          <bodyName>base_link</bodyName>
          <gaussianNoise>0</gaussianNoise>
          <rpyOffsets>0 0 0</rpyOffsets>
          <updateRate>5.0</updateRate>
          <alwaysOn>true</alwaysOn>
          <gaussianNoise>0</gaussianNoise>
        </plugin>
    </gazebo>



</robot>
